Workbook

Sheet foodpanda_orders
A1: Sl No | B1: Restaurant Names | C1: Date | D1: Time | E1: Day | F1: Month | G1: Year | H1: Service Status (Pick-up/Delivery) | I1: Order ID | J1: Price | K1: Items Line 1 | L1: Item Line 2 | M1: Item Line 3 | N1: Item Count | O1: Primary Item | P1: Cuisine | Q1: Ratings
A2: 1 | B2: ZAFRAN RESTORA & KABAB | C2: 46154 | D2: 0.84583333 | E2: Tue | F2: May | G2: 2026 | H2: Pick-up | I2: Order #xykb-2620-q1j9 | J2: 567 | K2: 1x Grilled Chicken, | L2: 1x Grilled Chicken | M2: - | N2: {=SUMPRODUCT(--(TRIM(K2:M2)<>"-")*(TRIM(K2:M2)<>"")*(ISTEXT(K2:M2)))} -> 2 | O2: Grilled Chicken | P2: {=IFERROR(INDEX('Cuisine Mapping'!$B$2:$B$71, MATCH(TRUE, ISNUMBER(SEARCH('Cuisine Mapping'!$A$2:$A$71,foodpanda_orders!$O2)),0)),"Others")} -> Kabab/Grill | Q2: 3
A3: 2 | B3: RICE AND NOODLE | C3: 46152 | D3: 0.94513889 | E3: Sun | F3: May | G3: 2026 | H3: Delivery | I3: Order #s6hq-2619-bp07 | J3: 834 | K3: 1x Ekushe Platter | L3: - | M3: - | N3: {=SUMPRODUCT(--(TRIM(K3:M3)<>"-")*(TRIM(K3:M3)<>"")*(ISTEXT(K3:M3)))} -> 1 | O3: Ekushe Platter | P3: {=IFERROR(INDEX('Cuisine Mapping'!$B$2:$B$71, MATCH(TRUE, ISNUMBER(SEARCH('Cuisine Mapping'!$A$2:$A$71,foodpanda_orders!$O3)),0)),"Others")} -> Others | Q3: 0
A4: 3 | B4: ZAFRAN RESTORA & KABAB | C4: 46148 | D4: 0.95625 | E4: Wed | F4: May | G4: 2026 | H4: Cancelled | I4: Order #xykb-2619-lnvq | J4: 270 | K4: 1x Grilled Chicken, | L4: 1x Grilled Chicken, | M4: 2x Plain Naan | N4: {=SUMPRODUCT(--(TRIM(K4:M4)<>"-")*(TRIM(K4:M4)<>"")*(ISTEXT(K4:M4)))} -> 3 | O4: Grilled Chicken | P4: {=IFERROR(INDEX('Cuisine Mapping'!$B$2:$B$71, MATCH(TRUE, ISNUMBER(SEARCH('Cuisine Mapping'!$A$2:$A$71,foodpanda_orders!$O4)),0)),"Others")} -> Kabab/Grill | Q4: 0
A5: 4 | B5: DREAM BURGER | C5: 46148 | D5: 0.025694444 | E5: Wed | F5: May | G5: 2026 | H5: Delivery | I5: Order #ge20-2619-3sma | J5: 307 | K5: 1x Chicken Cheese Burger, | L5: 1x French Fries | M5: - | N5: {=SUMPRODUCT(--(TRIM(K5:M5)<>"-")*(TRIM(K5:M5)<>"")*(ISTEXT(K5:M5)))} -> 2 | O5: Chicken Cheese Burger | P5: {=IFERROR(INDEX('Cuisine Mapping'!$B$2:$B$71, MATCH(TRUE, ISNUMBER(SEARCH('Cuisine Mapping'!$A$2:$A$71,foodpanda_orders!$O5)),0)),"Others")} -> American/Fast Food | Q5: 0
A6: 5 | B6: TWELVE30 CAFE | C6: 46148 | D6: 0.018055556 | E6: Wed | F6: May | G6: 2026 | H6: Cancelled | I6: Cancelled on Wed, May 6, 12:26 AM | J6: 372 | K6: 1x Twelve 30 Special Burger | L6: 1x Twelve 30 Special Burger | M6: - | N6: {=SUMPRODUCT(--(TRIM(K6:M6)<>"-")*(TRIM(K6:M6)<>"")*(ISTEXT(K6:M6)))} -> 2 | O6: Twelve 30 Special Burger | P6: {=IFERROR(INDEX('Cuisine Mapping'!$B$2:$B$71, MATCH(TRUE, ISNUMBER(SEARCH('Cuisine Mapping'!$A$2:$A$71,foodpanda_orders!$O6)),0)),"Others")} -> American/Fast Food | Q6: 0
A7: 6 | B7: BURGER XPRESS | C7: 46143 | D7: 0.93125 | E7: Fri | F7: May | G7: 2026 | H7: Delivery | I7: Order #dpzp-2618-00ku | J7: 345 | K7: 1x Chicken & Bacon House Burger | L7: - | M7: - | N7: {=SUMPRODUCT(--(TRIM(K7:M7)<>"-")*(TRIM(K7:M7)<>"")*(ISTEXT(K7:M7)))} -> 1 | O7: Chicken & Bacon House Burger | P7: {=IFERROR(INDEX('Cuisine Mapping'!$B$2:$B$71, MATCH(TRUE, ISNUMBER(SEARCH('Cuisine Mapping'!$A$2:$A$71,foodpanda_orders!$O7)),0)),"Others")} -> American/Fast Food | Q7: 0
A8: 7 | B8: TEHARI GHAR + | C8: 46143 | D8: 0.86666667 | E8: Fri | F8: May | G8: 2026 | H8: Delivery | I8: Order #rl1p-2618-c1e1 | J8: 303 | K8: 1x Beef Tehari | L8: - | M8: - | N8: {=SUMPRODUCT(--(TRIM(K8:M8)<>"-")*(TRIM(K8:M8)<>"")*(ISTEXT(K8:M8)))} -> 1 | O8: Beef Tehari | P8: {=IFERROR(INDEX('Cuisine Mapping'!$B$2:$B$71, MATCH(TRUE, ISNUMBER(SEARCH('Cuisine Mapping'!$A$2:$A$71,foodpanda_orders!$O8)),0)),"Others")} -> Bengali/Desi | Q8: 0
A9: 8 | B9: CRISP | C9: 46139 | D9: 0.94166667 | E9: Mon | F9: April | G9: 2026 | H9: Delivery | I9: Order #sxmo-2618-rhzn | J9: 558 | K9: 2x Hot and Lemony Chicken Rice Bowl | L9: - | M9: - | N9: {=SUMPRODUCT(--(TRIM(K9:M9)<>"-")*(TRIM(K9:M9)<>"")*(ISTEXT(K9:M9)))} -> 1 | O9: Hot and Lemony Chicken Rice Bowl | P9: {=IFERROR(INDEX('Cuisine Mapping'!$B$2:$B$71, MATCH(TRUE, ISNUMBER(SEARCH('Cuisine Mapping'!$A$2:$A$71,foodpanda_orders!$O9)),0)),"Others")} -> Rice Bowls | Q9: 0
A10: 9 | B10: BURGER XPRESS | C10: 46136 | D10: 0.91319444 | E10: Fri | F10: April | G10: 2026 | H10: Delivery | I10: Order #dpzp-2617-95j4 | J10: 360 | K10: 1x Chicken Pops, | L10: 1x Mexican Hot & Spicy Nachos | M10: - | N10: {=SUMPRODUCT(--(TRIM(K10:M10)<>"-")*(TRIM(K10:M10)<>"")*(ISTEXT(K10:M10)))} -> 2 | O10: Chicken Pops | P10: American/Fast Food | Q10: 0
A11: 10 | B11: BURGER XPRESS | C11: 46129 | D11: 0.94583333 | E11: Fri | F11: April | G11: 2026 | H11: Delivery | I11: Order #dpzp-2616-8ka3 | J11: 320 | K11: 1x Beef Caramel Mushroom Thrill Burger | L11: - | M11: - | N11: {=SUMPRODUCT(--(TRIM(K11:M11)<>"-")*(TRIM(K11:M11)<>"")*(ISTEXT(K11:M11)))} -> 1 | O11: Beef Caramel Mushroom Thrill Burger | P11: {=IFERROR(INDEX('Cuisine Mapping'!$B$2:$B$71, MATCH(TRUE, ISNUMBER(SEARCH('Cuisine Mapping'!$A$2:$A$71,foodpanda_orders!$O11)),0)),"Others")} -> American/Fast Food | Q11: 0
A12: 11 | B12: BURGER XPRESS | C12: 46129 | D12: 0.94305556 | E12: Fri | F12: April | G12: 2026 | H12: Delivery | I12: Order #dpzp-2616-o5a3 | J12: 329 | K12: 1x Beef & Bacon House Burger | L12: - | M12: - | N12: {=SUMPRODUCT(--(TRIM(K12:M12)<>"-")*(TRIM(K12:M12)<>"")*(ISTEXT(K12:M12)))} -> 1 | O12: Beef & Bacon House Burger | P12: {=IFERROR(INDEX('Cuisine Mapping'!$B$2:$B$71, MATCH(TRUE, ISNUMBER(SEARCH('Cuisine Mapping'!$A$2:$A$71,foodpanda_orders!$O12)),0)),"Others")} -> American/Fast Food | Q12: 0
A13: 12 | B13: TEHARI DEWAANA | C13: 46128 | D13: 0.68541667 | E13: Thu | F13: April | G13: 2026 | H13: Delivery | I13: Order #oo81-2616-anwk | J13: 255 | K13: 1x Polao with Chicken Angara | L13: - | M13: - | N13: {=SUMPRODUCT(--(TRIM(K13:M13)<>"-")*(TRIM(K13:M13)<>"")*(ISTEXT(K13:M13)))} -> 1 | O13: Polao with Chicken Angara | P13: {=IFERROR(INDEX('Cuisine Mapping'!$B$2:$B$71, MATCH(TRUE, ISNUMBER(SEARCH('Cuisine Mapping'!$A$2:$A$71,foodpanda_orders!$O13)),0)),"Others")} -> Bengali/Desi | Q13: 0
A14: 13 | B14: KABAB XPRESS | C14: 46125 | D14: 0.76597222 | E14: Mon | F14: April | G14: 2026 | H14: Delivery | I14: Order #nqh7-2616-792w | J14: 250 | K14: 1x Beef Butter Masala | L14: - | M14: - | N14: {=SUMPRODUCT(--(TRIM(K14:M14)<>"-")*(TRIM(K14:M14)<>"")*(ISTEXT(K14:M14)))} -> 1 | O14: Beef Butter Masala | P14: {=IFERROR(INDEX('Cuisine Mapping'!$B$2:$B$71, MATCH(TRUE, ISNUMBER(SEARCH('Cuisine Mapping'!$A$2:$A$71,foodpanda_orders!$O14)),0)),"Others")} -> Bengali/Desi | Q14: 1
A15: 14 | B15: MADCHEF | C15: 46123 | D15: 0.81597222 | E15: Sat | F15: April | G15: 2026 | H15: Delivery | I15: Order #s9vx-2615-8lmf | J15: 850 | K15: 1x Signature Beef, | L15: 1x Signature Chicken, | M15: 1x Paneer Sticks | N15: {=SUMPRODUCT(--(TRIM(K15:M15)<>"-")*(TRIM(K15:M15)<>"")*(ISTEXT(K15:M15)))} -> 3 | O15: Signature Beef | P15: American/Fast Food | Q15: 4
A16: 15 | B16: DIP FRY AND STEAK | C16: 46116 | D16: 0.67361111 | E16: Sat | F16: April | G16: 2026 | H16: Delivery | I16: Order #maw2-2614-9q2q | J16: 296 | K16: 1x Parmilcious Fried Chicken | L16: - | M16: - | N16: {=SUMPRODUCT(--(TRIM(K16:M16)<>"-")*(TRIM(K16:M16)<>"")*(ISTEXT(K16:M16)))} -> 1 | O16: Parmilcious Fried Chicken | P16: American/Fast Food | Q16: 3
A17: 16 | B17: DIBBLES | C17: 46112 | D17: 0.86041667 | E17: Tue | F17: March | G17: 2026 | H17: Delivery | I17: Order #oid3-2614-4f3z | J17: 479 | K17: 1x Nashville Hot Dirty Fries, | L17: 1x OG Dirty Fries | M17: - | N17: {=SUMPRODUCT(--(TRIM(K17:M17)<>"-")*(TRIM(K17:M17)<>"")*(ISTEXT(K17:M17)))} -> 2 | O17: Nashville Hot Dirty Fries | P17: {=IFERROR(INDEX('Cuisine Mapping'!$B$2:$B$71, MATCH(TRUE, ISNUMBER(SEARCH('Cuisine Mapping'!$A$2:$A$71,foodpanda_orders!$O17)),0)),"Others")} -> American/Fast Food | Q17: 0
A18: 17 | B18: ZAFRAN RESTORA & KABAB | C18: 46110 | D18: 0.75138889 | E18: Sun | F18: March | G18: 2026 | H18: Delivery | I18: Order #xykb-2613-zw5u | J18: 174 | K18: 1x Grilled Chicken, | L18: 3x Plain Naan | M18: - | N18: {=SUMPRODUCT(--(TRIM(K18:M18)<>"-")*(TRIM(K18:M18)<>"")*(ISTEXT(K18:M18)))} -> 2 | O18: Grilled Chicken | P18: {=IFERROR(INDEX('Cuisine Mapping'!$B$2:$B$71, MATCH(TRUE, ISNUMBER(SEARCH('Cuisine Mapping'!$A$2:$A$71,foodpanda_orders!$O18)),0)),"Others")} -> Kabab/Grill | Q18: 0
A19: 18 | B19: CHILLOX | C19: 46110 | D19: 0 | E19: Sun | F19: March | G19: 2026 | H19: Delivery | I19: Order #s3ac-2613-0vu5 | J19: 363 | K19: 1x Crispy Chicken Burger, | L19: 1x Fish Tots | M19: - | N19: {=SUMPRODUCT(--(TRIM(K19:M19)<>"-")*(TRIM(K19:M19)<>"")*(ISTEXT(K19:M19)))} -> 2 | O19: Crispy Chicken Burger | P19: {=IFERROR(INDEX('Cuisine Mapping'!$B$2:$B$71, MATCH(TRUE, ISNUMBER(SEARCH('Cuisine Mapping'!$A$2:$A$71,foodpanda_orders!$O19)),0)),"Others")} -> American/Fast Food | Q19: 0
A20: 19 | B20: UNCLE BOBO'S | C20: 46108 | D20: 0.047916667 | E20: Fri | F20: March | G20: 2026 | H20: Delivery | I20: Order #yxgi-2613-yngh | J20: 277 | K20: 1x XXL Fried Chicken - Smokey Lime, | L20: 1x Fried Rice, | M20: 1x Coleslaw | N20: {=SUMPRODUCT(--(TRIM(K20:M20)<>"-")*(TRIM(K20:M20)<>"")*(ISTEXT(K20:M20)))} -> 3 | O20: XXL Fried Chicken - Smokey Lime | P20: American/Fast Food | Q20: 2
A21: 20 | B21: MADCHEF | C21: 46105 | D21: 0.85972222 | E21: Tue | F21: March | G21: 2026 | H21: Delivery | I21: Order #s9vx-2613-aw3z | J21: 548 | K21: 1x Signature Chicken, | L21: 1x Bomb Fries | M21: - | N21: {=SUMPRODUCT(--(TRIM(K21:M21)<>"-")*(TRIM(K21:M21)<>"")*(ISTEXT(K21:M21)))} -> 2 | O21: Signature Chicken | P21: American/Fast Food | Q21: 0
A22: 21 | B22: CHEEZ | C22: 46102 | D22: 0.85138889 | E22: Sat | F22: March | G22: 2026 | H22: Delivery | I22: Order #s6ka-2612-dqvm | J22: 1855 | K22: 1x Bestseller Combo | L22: - | M22: - | N22: {=SUMPRODUCT(--(TRIM(K22:M22)<>"-")*(TRIM(K22:M22)<>"")*(ISTEXT(K22:M22)))} -> 1 | O22: Bestseller Combo | P22: {=IFERROR(INDEX('Cuisine Mapping'!$B$2:$B$71, MATCH(TRUE, ISNUMBER(SEARCH('Cuisine Mapping'!$A$2:$A$71,foodpanda_orders!$O22)),0)),"Others")} -> Others | Q22: 0
A23: 22 | B23: DIP FRY AND STEAK | C23: 46101 | D23: 0.022222222 | E23: Fri | F23: March | G23: 2026 | H23: Delivery | I23: Order #maw2-2612-r97a | J23: 326 | K23: 1x Classic Crispy Chicken Burger | L23: - | M23: - | N23: {=SUMPRODUCT(--(TRIM(K23:M23)<>"-")*(TRIM(K23:M23)<>"")*(ISTEXT(K23:M23)))} -> 1 | O23: Classic Crispy Chicken Burger | P23: {=IFERROR(INDEX('Cuisine Mapping'!$B$2:$B$71, MATCH(TRUE, ISNUMBER(SEARCH('Cuisine Mapping'!$A$2:$A$71,foodpanda_orders!$O23)),0)),"Others")} -> American/Fast Food | Q23: 0
A24: 23 | B24: SMASHED BURGERS | C24: 46099 | D24: 0.66111111 | E24: Wed | F24: March | G24: 2026 | H24: Delivery | I24: Order #ds3b-2612-ecel | J24: 486 | K24: 1x Honeyfire Chicken, | L24: 1x Parmesan Fries | M24: - | N24: {=SUMPRODUCT(--(TRIM(K24:M24)<>"-")*(TRIM(K24:M24)<>"")*(ISTEXT(K24:M24)))} -> 2 | O24: Honeyfire Chicken | P24: American/Fast Food | Q24: 0
A25: 24 | B25: MADCHEF | C25: 46096 | D25: 0.033333333 | E25: Sun | F25: March | G25: 2026 | H25: Delivery | I25: Order #s9vx-2611-va7x | J25: 496 | K25: 1x Bomb Fries, | L25: 1x OG Cheez Fries | M25: - | N25: {=SUMPRODUCT(--(TRIM(K25:M25)<>"-")*(TRIM(K25:M25)<>"")*(ISTEXT(K25:M25)))} -> 2 | O25: Bomb Fries | P25: {=IFERROR(INDEX('Cuisine Mapping'!$B$2:$B$71, MATCH(TRUE, ISNUMBER(SEARCH('Cuisine Mapping'!$A$2:$A$71,foodpanda_orders!$O25)),0)),"Others")} -> American/Fast Food | Q25: 0
A26: 25 | B26: CAFE CINO | C26: 46093 | D26: 0.91736111 | E26: Thu | F26: March | G26: 2026 | H26: Delivery | I26: Order #scgo-2611-s99d | J26: 728 | K26: 2x Chicken Cashewnut Salad | L26: - | M26: - | N26: {=SUMPRODUCT(--(TRIM(K26:M26)<>"-")*(TRIM(K26:M26)<>"")*(ISTEXT(K26:M26)))} -> 1 | O26: Chicken Cashewnut Salad | P26: {=IFERROR(INDEX('Cuisine Mapping'!$B$2:$B$71, MATCH(TRUE, ISNUMBER(SEARCH('Cuisine Mapping'!$A$2:$A$71,foodpanda_orders!$O26)),0)),"Others")} -> Salads/Light | Q26: 0
A27: 26 | B27: DONERCI FLAMING DONER | C27: 46091 | D27: 0.75069444 | E27: Tue | F27: March | G27: 2026 | H27: Delivery | I27: Order #tjf4-2611-r24g | J27: 1376 | K27: 1x Meaty Mighty Box - 1 | L27: - | M27: - | N27: {=SUMPRODUCT(--(TRIM(K27:M27)<>"-")*(TRIM(K27:M27)<>"")*(ISTEXT(K27:M27)))} -> 1 | O27: Meaty Mighty Box - 1 | P27: American/Fast Food | Q27: 0
A28: 27 | B28: DEKCHI | C28: 46085 | D28: 0.95694444 | E28: Wed | F28: March | G28: 2026 | H28: Delivery | I28: Order #quzt-2610-5kx1 | J28: 448 | K28: 1x Shahi Morog Polao, | L28: 1x Nawabi Crumb Roast | M28: - | N28: {=SUMPRODUCT(--(TRIM(K28:M28)<>"-")*(TRIM(K28:M28)<>"")*(ISTEXT(K28:M28)))} -> 2 | O28: Shahi Morog Polao | P28: {=IFERROR(INDEX('Cuisine Mapping'!$B$2:$B$71, MATCH(TRUE, ISNUMBER(SEARCH('Cuisine Mapping'!$A$2:$A$71,foodpanda_orders!$O28)),0)),"Others")} -> Bengali/Desi | Q28: 0
A29: 28 | B29: BURGER XPRESS | C29: 46084 | D29: 0.99791667 | E29: Tue | F29: March | G29: 2026 | H29: Delivery | I29: Order #dpzp-2610-nbbi | J29: 329 | K29: 1x Peri Peri French Fries, | L29: 1x Double Decker Chicken Burger | M29: - | N29: {=SUMPRODUCT(--(TRIM(K29:M29)<>"-")*(TRIM(K29:M29)<>"")*(ISTEXT(K29:M29)))} -> 2 | O29: Peri Peri French Fries | P29: {=IFERROR(INDEX('Cuisine Mapping'!$B$2:$B$71, MATCH(TRUE, ISNUMBER(SEARCH('Cuisine Mapping'!$A$2:$A$71,foodpanda_orders!$O29)),0)),"Others")} -> American/Fast Food | Q29: 0
A30: 29 | B30: PROTEIN CORNER | C30: 46078 | D30: 0.93680556 | E30: Wed | F30: February | G30: 2026 | H30: Delivery | I30: Order #oqd6-2609-jlcp | J30: 359 | K30: 1x Cashewnut Salad | L30: - | M30: - | N30: {=SUMPRODUCT(--(TRIM(K30:M30)<>"-")*(TRIM(K30:M30)<>"")*(ISTEXT(K30:M30)))} -> 1 | O30: Cashewnut Salad | P30: {=IFERROR(INDEX('Cuisine Mapping'!$B$2:$B$71, MATCH(TRUE, ISNUMBER(SEARCH('Cuisine Mapping'!$A$2:$A$71,foodpanda_orders!$O30)),0)),"Others")} -> Salads/Light | Q30: 0
A31: 30 | B31: CHEEZ | C31: 46073 | D31: 0.98055556 | E31: Fri | F31: February | G31: 2026 | H31: Delivery | I31: Order #s6ka-2608-eq70 | J31: 537 | K31: 1x Cheezy Garlic Bread, | L31: 1x Spicy Sausage Garlic | M31: - | N31: {=SUMPRODUCT(--(TRIM(K31:M31)<>"-")*(TRIM(K31:M31)<>"")*(ISTEXT(K31:M31)))} -> 2 | O31: Cheezy Garlic Bread | P31: Italian/Pizza | Q31: 0
A32: 31 | B32: DEKCHI | C32: 46063 | D32: 0.90416667 | E32: Tue | F32: February | G32: 2026 | H32: Delivery | I32: Order #quzt-2607-xcvm | J32: 668 | K32: 2x Biye Bari Khana | L32: - | M32: - | N32: {=SUMPRODUCT(--(TRIM(K32:M32)<>"-")*(TRIM(K32:M32)<>"")*(ISTEXT(K32:M32)))} -> 1 | O32: Biye Bari Khana | P32: {=IFERROR(INDEX('Cuisine Mapping'!$B$2:$B$71, MATCH(TRUE, ISNUMBER(SEARCH('Cuisine Mapping'!$A$2:$A$71,foodpanda_orders!$O32)),0)),"Others")} -> Bengali/Desi | Q32: 0
A33: 32 | B33: HAMZA BIRIYANI | C33: 46056 | D33: 0.925 | E33: Tue | F33: February | G33: 2026 | H33: Delivery | I33: Order #ikbd-2606-muhi | J33: 406 | K33: 2x Morog Polao | L33: - | M33: - | N33: {=SUMPRODUCT(--(TRIM(K33:M33)<>"-")*(TRIM(K33:M33)<>"")*(ISTEXT(K33:M33)))} -> 1 | O33: Morog Polao | P33: {=IFERROR(INDEX('Cuisine Mapping'!$B$2:$B$71, MATCH(TRUE, ISNUMBER(SEARCH('Cuisine Mapping'!$A$2:$A$71,foodpanda_orders!$O33)),0)),"Others")} -> Bengali/Desi | Q33: 0
A34: 33 | B34: DEKCHI | C34: 46052 | D34: 0.91527778 | E34: Fri | F34: January | G34: 2026 | H34: Delivery | I34: Order #quzt-2605-wfcm | J34: 376 | K34: 1x Classic Chicken Biryani, | L34: 1x Shahi Jorda | M34: - | N34: {=SUMPRODUCT(--(TRIM(K34:M34)<>"-")*(TRIM(K34:M34)<>"")*(ISTEXT(K34:M34)))} -> 2 | O34: Classic Chicken Biryani | P34: Bengali/Desi | Q34: 0
A35: 34 | B35: PAGLA BABURCHI | C35: 46052 | D35: 0.91527778 | E35: Fri | F35: January | G35: 2026 | H35: Delivery | I35: Order #ml4c-2605-go58 | J35: 491 | K35: 1x Mad Kacchi, | L35: 1x Chicken Tikka Jali Kebab | M35: - | N35: {=SUMPRODUCT(--(TRIM(K35:M35)<>"-")*(TRIM(K35:M35)<>"")*(ISTEXT(K35:M35)))} -> 2 | O35: Mad Kacchi | P35: {=IFERROR(INDEX('Cuisine Mapping'!$B$2:$B$71, MATCH(TRUE, ISNUMBER(SEARCH('Cuisine Mapping'!$A$2:$A$71,foodpanda_orders!$O35)),0)),"Others")} -> Bengali/Desi | Q35: 0
A36: 35 | B36: CHILLOX | C36: 46049 | D36: 0.975 | E36: Tue | F36: January | G36: 2026 | H36: Delivery | I36: Order #s3ac-2605-kv1c | J36: 490 | K36: 1x Double Decker Chicken Burger, | L36: 1x Fried Chicken | M36: - | N36: {=SUMPRODUCT(--(TRIM(K36:M36)<>"-")*(TRIM(K36:M36)<>"")*(ISTEXT(K36:M36)))} -> 2 | O36: Double Decker Chicken Burger | P36: {=IFERROR(INDEX('Cuisine Mapping'!$B$2:$B$71, MATCH(TRUE, ISNUMBER(SEARCH('Cuisine Mapping'!$A$2:$A$71,foodpanda_orders!$O36)),0)),"Others")} -> American/Fast Food | Q36: 0
A37: 36 | B37: SMASHED BURGERS | C37: 46046 | D37: 0.63263889 | E37: Sat | F37: January | G37: 2026 | H37: Delivery | I37: Order #ds3b-2604-75k5 | J37: 497 | K37: 1x All American BBQ Bacon Beef Burger, | L37: 1x French Fries | M37: - | N37: {=SUMPRODUCT(--(TRIM(K37:M37)<>"-")*(TRIM(K37:M37)<>"")*(ISTEXT(K37:M37)))} -> 2 | O37: All American BBQ Bacon Beef Burger | P37: {=IFERROR(INDEX('Cuisine Mapping'!$B$2:$B$71, MATCH(TRUE, ISNUMBER(SEARCH('Cuisine Mapping'!$A$2:$A$71,foodpanda_orders!$O37)),0)),"Others")} -> American/Fast Food | Q37: 0
A38: 37 | B38: SMASHED BURGERS | C38: 46046 | D38: 0.63125 | E38: Sat | F38: January | G38: 2026 | H38: Delivery | I38: Order #ds3b-2604-nfv0 | J38: 529 | K38: 1x Mustard Drizzled Beef Burger, | L38: 1x French Fries | M38: - | N38: {=SUMPRODUCT(--(TRIM(K38:M38)<>"-")*(TRIM(K38:M38)<>"")*(ISTEXT(K38:M38)))} -> 2 | O38: Mustard Drizzled Beef Burger | P38: {=IFERROR(INDEX('Cuisine Mapping'!$B$2:$B$71, MATCH(TRUE, ISNUMBER(SEARCH('Cuisine Mapping'!$A$2:$A$71,foodpanda_orders!$O38)),0)),"Others")} -> American/Fast Food | Q38: 0
A39: 38 | B39: CRISP | C39: 46045 | D39: 0.00069444444 | E39: Fri | F39: January | G39: 2026 | H39: Delivery | I39: Order #sxmo-2604-f1pl | J39: 488 | K39: 1x Crispy Chicken Burger, | L39: 1x Crispy Chicken Popcorn | M39: - | N39: {=SUMPRODUCT(--(TRIM(K39:M39)<>"-")*(TRIM(K39:M39)<>"")*(ISTEXT(K39:M39)))} -> 2 | O39: Crispy Chicken Burger | P39: {=IFERROR(INDEX('Cuisine Mapping'!$B$2:$B$71, MATCH(TRUE, ISNUMBER(SEARCH('Cuisine Mapping'!$A$2:$A$71,foodpanda_orders!$O39)),0)),"Others")} -> American/Fast Food | Q39: 0
A40: 39 | B40: CITY RESTAURANT | C40: 46036 | D40: 0.53125 | E40: Wed | F40: January | G40: 2026 | H40: Delivery | I40: Order #rwgg-2603-xm8g | J40: 812 | K40: 1x Beef Lal Bhuna | L40: - | M40: - | N40: {=SUMPRODUCT(--(TRIM(K40:M40)<>"-")*(TRIM(K40:M40)<>"")*(ISTEXT(K40:M40)))} -> 1 | O40: Beef Lal Bhuna | P40: {=IFERROR(INDEX('Cuisine Mapping'!$B$2:$B$71, MATCH(TRUE, ISNUMBER(SEARCH('Cuisine Mapping'!$A$2:$A$71,foodpanda_orders!$O40)),0)),"Others")} -> Bengali/Desi | Q40: 0
...

Sheet Cuisine Mapping
A1: Keyword | B1: Cuisine
A2: khichuri | B2: Bengali/Desi
A3: kacchi | B3: Bengali/Desi
A4: tehari | B4: Bengali/Desi
A5: polao | B5: Bengali/Desi
A6: morog | B6: Bengali/Desi
A7: haleem | B7: Bengali/Desi
A8: jorda | B8: Bengali/Desi
A9: paratha | B9: Bengali/Desi
A10: parata | B10: Bengali/Desi
A11: chui gosht | B11: Bengali/Desi
A12: karahi | B12: Bengali/Desi
... A71: cola | B71: Beverages
